<?xml version="1.0" ?>
<!-- =================================================================================== -->
<!-- |    This document was autogenerated by xacro from /Users/amorales/Documents/IEEE/2022/RAS/chessbot/chessbot/chessbot_ws/src/chessbot_robot/urdf/irb140.xacro | -->
<!-- |    EDITING THIS FILE BY HAND IS NOT RECOMMENDED                                 | -->
<!-- =================================================================================== -->
<robot name="abb_irb140">
      <material name="abb_orange">
        <color rgba="1 0.43 0 1"/>
      </material>
      <material name="yellow">
        <color rgba="0 1 1 1"/>
      </material>

  <!-- link list -->
  <link name="base_link">
    <visual>
      <origin rpy="0 0 0" xyz="0 0 0"/>
      <geometry>
        <mesh filename="package://chessbot_robot/meshes/irb140/visual/base_link.stl" scale="0.01 0.01 0.01"/>
      </geometry>
      <material name="abb_orange"/>
      
    </visual>
    <collision>
      <geometry>
        <mesh filename="package://chessbot_robot/meshes/irb140/collision/base_link.stl" scale="0.01 0.01 0.01"/>
      </geometry>
      <material name="yellow"/>
    
    </collision>
  </link>
  <link name="link_1">
    <visual>
      <origin rpy="0 0 0" xyz="0 0 0"/>
      <geometry>
        <mesh filename="package://chessbot_robot/meshes/irb140/visual/link_1.stl" scale="0.01 0.01 0.01"/>
      </geometry>
      <material name="abb_orange"/>
    </visual>
    <collision>
      <origin rpy="0 0 0" xyz="0 0 0"/>
      <geometry>
        <mesh filename="package://chessbot_robot/meshes/irb140/collision/link_1.stl" scale="0.01 0.01 0.01"/>
      </geometry>
      <material name="yellow"/>
    </collision>
  </link>
  <link name="link_2">
    <visual>
      <origin rpy="0 0 0" xyz="-0.07 0 -0.352"/>
      <geometry>
        <mesh filename="package://chessbot_robot/meshes/irb140/visual/link_2.stl" scale="0.01 0.01 0.01"/>
      </geometry>
      <material name="abb_orange"/>
    </visual>
    <collision>
      <origin rpy="0 0 0" xyz="-0.07 0 -0.352"/>
      <geometry>
        <mesh filename="package://chessbot_robot/meshes/irb140/collision/link_2.stl" scale="0.01 0.01 0.01"/>
      </geometry>
      <material name="yellow"/>
    </collision>
  </link>
  <link name="link_3">
    <visual>
      <origin rpy="0 0 0" xyz="-0.07 0.065 -0.712"/>
      <geometry>
        <mesh filename="package://chessbot_robot/meshes/irb140/visual/link_3.stl" scale="0.01 0.01 0.01"/>
      </geometry>
      <material name="abb_orange"/>
    </visual>
    <collision>
      <origin rpy="0 0 0" xyz="-0.07 0.065 -0.712"/>
      <geometry>
        <mesh filename="package://chessbot_robot/meshes/irb140/collision/link_3.stl" scale="0.01 0.01 0.01"/>
      </geometry>
      <material name="yellow"/>
    </collision>
  </link>
  <link name="link_4">
    <visual>
      <origin rpy="0 0 0" xyz="-0.309 0 -0.712"/>
      <geometry>
        <mesh filename="package://chessbot_robot/meshes/irb140/visual/link_4.stl" scale="0.01 0.01 0.01"/>
      </geometry>
      <material name="abb_orange"/>
    </visual>
    <collision>
      <origin rpy="0 0 0" xyz="-0.309 0 -0.712"/>
      <geometry>
        <mesh filename="package://chessbot_robot/meshes/irb140/collision/link_4.stl" scale="0.01 0.01 0.01"/>
      </geometry>
      <material name="yellow"/>
    </collision>
  </link>
  <link name="link_5">
    <visual>
      <origin rpy="0 0 0" xyz="-0.450 0 -0.712"/>
      <geometry>
        <mesh filename="package://chessbot_robot/meshes/irb140/visual/link_5.stl" scale="0.01 0.01 0.01"/>
      </geometry>
      <material name="abb_orange"/>
    </visual>
    <collision>
      <origin rpy="0 0 0" xyz="-0.450 0 -0.712"/>
      <geometry>
        <mesh filename="package://chessbot_robot/meshes/irb140/collision/link_5.stl" scale="0.01 0.01 0.01"/>
      </geometry>
      <material name="yellow"/>
    </collision>
  </link>
  <link name="link_6">
    <visual>
      <origin rpy="0 0 0" xyz="-0.515 0 -0.712"/>
      <geometry>
        <mesh filename="package://chessbot_robot/meshes/irb140/visual/link_6.stl" scale="0.01 0.01 0.01"/>
      </geometry>
      <material name="abb_orange"/>
    </visual>
    <collision>
      <origin rpy="0 0 0" xyz="-0.515 0 -0.712"/>
      <geometry>
        <mesh filename="package://chessbot_robot/meshes/irb140/collision/link_6.stl" scale="0.01 0.01 0.01"/>
      </geometry>
      <material name="yellow"/>
    </collision>
  </link>
  <link name="tool0"/>
  <!-- end of link list -->
  <!-- joint list -->
  <joint name="joint_1" type="revolute">
    <origin rpy="0 0 0" xyz="0 0 0"/>
    <parent link="base_link"/>
    <child link="link_1"/>
    <axis xyz="0 0 1"/>
    <limit effort="0" lower="-3.1416" upper="3.1416" velocity="2.618"/>
  </joint>
  <joint name="joint_2" type="revolute">
    <origin rpy="0 0 0" xyz="0.070 0 0.352"/>
    <parent link="link_1"/>
    <child link="link_2"/>
    <axis xyz="0 1 0"/>
    <limit effort="0" lower="-1.7453" upper="1.7453" velocity="2.618"/>
  </joint>
  <joint name="joint_3" type="revolute">
    <origin rpy="0 0 0" xyz="0 -0.065 0.360"/>
    <parent link="link_2"/>
    <child link="link_3"/>
    <axis xyz="0 1 0"/>
    <limit effort="0" lower="-2.4434" upper="2.4434" velocity="2.618"/>
  </joint>
  <joint name="joint_4" type="revolute">
    <origin rpy="0 0 0" xyz="0.239 0.065 0"/>
    <parent link="link_3"/>
    <child link="link_4"/>
    <axis xyz="1 0 0"/>
    <limit effort="0" lower="-3.49" upper="3.49" velocity="6.2832"/>
  </joint>
  <joint name="joint_5" type="revolute">
    <origin rpy="0 0 0" xyz="0.141 0 0"/>
    <parent link="link_4"/>
    <child link="link_5"/>
    <axis xyz="0 1 0"/>
    <limit effort="0" lower="-2.0071" upper="2.0071" velocity="6.2832"/>
  </joint>
  <joint name="joint_6" type="revolute">
    <origin rpy="0 0 0" xyz="0.065 0 0"/>
    <parent link="link_5"/>
    <child link="link_6"/>
    <axis xyz="1 0 0"/>
    <limit effort="0" lower="-6.9813" upper="6.9813" velocity="7.854"/>
  </joint>
  <joint name="joint_6-tool0" type="fixed">
    <parent link="link_6"/>
    <child link="tool0"/>
    <origin rpy="0 0 0" xyz="0 0 0"/>
  </joint>
  <!-- end of joint list -->
  <!-- ROS base_link to ABB World Coordinates transform -->
  <link name="base"/>
  <joint name="base_link-base" type="fixed">
    <origin rpy="0 0 0" xyz="0 0 0"/>
    <parent link="base_link"/>
    <child link="base"/>
  </joint>
</robot>
